#VRML_SIM R2019a utf8
WorldInfo {
}
Viewpoint {
  orientation -0.9917758682105967 -0.125561175868623 -0.024799563496277793 0.39315166357202336
  position -0.5387534446852685 1.6391919779685855 2.759356391740311
}
TexturedBackground {
}
TexturedBackgroundLight {
}
Floor {
}
Solid {
  children [
    DEF GROUP1 Group {
      children [
        Transform {
          translation 0 0.347 0
          rotation 1 0 0 0.52
          children [
            Shape {
              appearance DEF COLOR_CHAIR_LEG PBRAppearance {
                baseColor 0.5333333333333333 0.5411764705882353 0.5215686274509804
                roughness 1
                metalness 0
              }
              geometry DEF SIZE_CHAIR_LEG Box {
                size 0.1 0.8 0.001
              }
            }
          ]
        }
        Transform {
          translation 0 0.347 0.5
          rotation 1 0 0 -0.52
          children [
            Shape {
              appearance USE COLOR_CHAIR_LEG
              geometry USE SIZE_CHAIR_LEG
            }
          ]
        }
        Transform {
          translation 0 0.34 0.2
          children [
            Shape {
              appearance USE COLOR_CHAIR_LEG
              geometry DEF SIZE_MIDDLE Box {
                size 0.1 0.01 0.4
              }
            }
          ]
        }
      ]
    }
    Transform {
      translation -1 0 0
      children [
        USE GROUP1
      ]
    }
    Transform {
      translation -0.5 0.69 0.25
      children [
        Shape {
          appearance USE COLOR_CHAIR_LEG
          geometry Box {
            size 1.1 0.01 0.1
          }
        }
      ]
    }
    HingeJoint {
      endPoint Solid {
        children [
          Shape {
          }
        ]
      }
    }
  ]
}
