#VRML_SIM R2019a utf8
WorldInfo {
}
Viewpoint {
  orientation -0.7215352031385167 0.6467665092832429 0.2471437498732838 0.9740860328442519
  position 1.3372598224866725 2.6946297269538246 2.4173746416751056
}
TexturedBackground {
}
TexturedBackgroundLight {
}
Floor {
}
Solid {
  children [
    DEF GROUP1 Group {
      children [
        Transform {
          translation 0 0.347 0
          rotation 1 0 0 0.52
          children [
            Shape {
              appearance DEF COLOR_CHAIR_LEG PBRAppearance {
                baseColor 0.12549019607843137 0.2901960784313726 0.5294117647058824
                roughness 1
                metalness 0
              }
              geometry DEF SIZE_CHAIR_LEG Box {
                size 0.1 0.8 0.001
              }
            }
          ]
        }
        Transform {
          translation 0 0.347 0.5
          rotation 1 0 0 -0.52
          children [
            Shape {
              appearance USE COLOR_CHAIR_LEG
              geometry USE SIZE_CHAIR_LEG
            }
          ]
        }
        Transform {
          translation 0 0.34 0.25
          children [
            Shape {
              appearance DEF COLOR_MIDDLE_TABLE PBRAppearance {
                baseColor 0.9607843137254902 0.4745098039215686 0
                roughness 1
                metalness 0
              }
              geometry DEF SIZE_MIDDLE Box {
                size 0.1 0.01 0.5
              }
            }
          ]
        }
      ]
    }
    Transform {
      translation -1 0 0
      children [
        USE GROUP1
      ]
    }
    Transform {
    }
    Transform {
      translation -0.5 0.69 0.25
      children [
        Shape {
          appearance USE COLOR_CHAIR_LEG
          geometry Box {
            size 1.1 0.01 0.1
          }
        }
      ]
    }
    HingeJoint {
      jointParameters HingeJointParameters {
        axis 0 1 0
        anchor -0.5 0.69 0.25
        staticFriction 0.05
      }
      endPoint Solid {
        translation -0.5 0.66 0.25
        children [
          Shape {
            appearance PBRAppearance {
              baseColor 0.9372549019607843 0.1607843137254902 0.1607843137254902
              roughness 1
              metalness 0
            }
            geometry Box {
              size 0.25 0.05 0.1
            }
          }
          HingeJoint {
            jointParameters HingeJointParameters {
              anchor 0 -0.025 0
              minStop -0.7853
              maxStop 0.7853
              staticFriction 0.01
            }
            endPoint Solid {
              translation 0 -0.21 0
              rotation 1 0 0 0
              children [
                Shape {
                  appearance PBRAppearance {
                    baseColor 0.9294117647058824 0.8313725490196079 0
                    roughness 1
                    metalness 0
                  }
                  geometry Cylinder {
                    height 0.4
                    radius 0.03
                  }
                }
                Transform {
                  translation 0 -0.27 0
                  children [
                    Shape {
                      appearance PBRAppearance {
                        baseColor 0.5411764705882353 0.8862745098039215 0.20392156862745098
                        roughness 1
                        metalness 0
                      }
                      geometry DEF BALL Sphere {
                        radius 0.08
                        subdivision 2
                      }
                    }
                  ]
                }
              ]
              name "solid(1)"
              physics Physics {
              }
            }
          }
        ]
        physics Physics {
        }
      }
    }
  ]
}
