#VRML_SIM R2019a utf8
WorldInfo {
}
Viewpoint {
  orientation -0.31620523429109665 -0.9486789497180642 -0.004743434277280161 0.03162265801408908
  position -0.5301385546206987 0.5447699405042388 1.7904740978906362
}
TexturedBackground {
}
TexturedBackgroundLight {
}
Floor {
}
Solid {
  children [
    DEF GROUP1 Group {
      children [
        Transform {
          translation 0 0.347 0
          rotation 1 0 0 0.52
          children [
            Shape {
              appearance DEF COLOR_CHAIR_LEG PBRAppearance {
                baseColor 0.5333333333333333 0.5411764705882353 0.5215686274509804
                roughness 1
                metalness 0
              }
              geometry DEF SIZE_CHAIR_LEG Box {
                size 0.1 0.8 0.001
              }
            }
          ]
        }
        Transform {
          translation 0 0.347 0.5
          rotation 1 0 0 -0.52
          children [
            Shape {
              appearance USE COLOR_CHAIR_LEG
              geometry USE SIZE_CHAIR_LEG
            }
          ]
        }
        Transform {
          translation 0 0.34 0.2
          children [
            Shape {
              appearance USE COLOR_CHAIR_LEG
              geometry DEF SIZE_MIDDLE Box {
                size 0.1 0.01 0.4
              }
            }
          ]
        }
      ]
    }
    Transform {
      translation -1 0 0
      children [
        USE GROUP1
      ]
    }
    Transform {
      translation -0.5 0.69 0.25
      children [
        Shape {
          appearance USE COLOR_CHAIR_LEG
          geometry Box {
            size 1.1 0.01 0.1
          }
        }
      ]
    }
    HingeJoint {
      jointParameters HingeJointParameters {
        axis 0 1 0
        anchor -0.5 0.69 0.25
      }
      endPoint Solid {
        translation -0.5 0.66 0.25
        children [
          Shape {
            appearance PBRAppearance {
              baseColor 0.9372549019607843 0.1607843137254902 0.1607843137254902
              roughness 1
              metalness 0
            }
            geometry Box {
              size 0.25 0.05 0.1
            }
          }
        ]
        physics Physics {
        }
      }
    }
    HingeJoint {
      jointParameters HingeJointParameters {
        anchor -0.5 0.64 0.25
      }
      endPoint Solid {
        translation -0.5 0.44 0.25
        children [
          Shape {
            appearance PBRAppearance {
              baseColor 0.9294117647058824 0.8313725490196079 0
              roughness 1
              metalness 0
            }
            geometry Cylinder {
              height 0.4
              radius 0.03
            }
          }
        ]
        name "solid(1)"
        physics Physics {
        }
      }
    }
  ]
}
